Workbook

Sheet 🏠 Home
A1: A&S Internship Program | Planning Log
A3: This is your PLANNING LOG. All completed work must also be entered in the electronic tracking form at the bottom of your Canvas course page. Set share settings to 'Anyone With the Link Can View' before submitting.
A5: THREE TYPES OF INTERNSHIP EXPERIENCES
A6: 🎓 EMBEDDED
B7: Fieldwork application assigned by the instructor to practice knowledge gained in the course. These experiences align directly to the course content and are submitted as part of the course assignment.
A8: 🔗 ALIGNED
B9: Fieldwork required as identified by the internship supervisor. These experiences connect course content to your specific school or division context and are tracked in this log.
A10: ⭐ CHOICE
B11: Interns engage in opportunities of choice, planned in addition to assigned experiences. Choice hours fill remaining competency gaps and are entered in the Choice Hours tab of this log. No activity may exceed 3 hours.
A13: HOW TO USE THIS LOG
A14: Step 1 | B14: Click the tab for the course you are enrolled in this semester (e.g., 7806, 7812).
A15: Step 2 | B15: Review the pre-filled Embedded and Aligned experiences. Enter the date, location, and your role.
A16: Step 3 | B16: The RED cell shows how many Choice hours you still need. Add your choice activities in the rows below it.
A17: Step 4 | B17: Mark ONE competency (1–6) per activity using 'X' in the competency columns.
A18: Step 5 | B18: Check the 📊 Dashboard tab to monitor your overall progress toward the 320-hour goal.
A19: Step 6 | B19: Enter all completed hours in the Canvas electronic tracking form. This log is your PLAN — Canvas is the RECORD.
A21: COURSE TABS QUICK REFERENCE | C21: 2nd Pathway Course Sequence
A22: Semester 1 | B22: 7806 – School & Community Relations | 7812 – Leading Continuous Improvement | C22: 7806 – School & Community Relations | 7812 – Leading Continuous Improvement
A23: Semester 2 | B23: 7807 – Leadership I | 7811 – Teaching & Learning | C23: 7807 – Leadership I | 7811 – Teaching & Learning
B24: 7140 -- Lead II. | 7810 – School Law | C24: 7805 – Cultivating Professional Capacity | 7810 – School Law
A25: Semester 4 | B25: 7808 – School Finance | 7805 – Cultivating Professional Capacity | C25: 7808 – School Finance | 7815 – Leadership for Diverse Learners
A26: Semester 5 | B26: 7813 – Educational Technology | 7815 – Leadership for Diverse Learners

Sheet 7806
A1: INTERNSHIP LOG | 7806 – School & Community Relations | Semester 1
A2: Name: Pat Example Placement(s): Invented Elementary | E2: Total Hours Logged | G2: =SUM(F6:F200) | H2: Remaining | J2: =(32-G2)
A3: Hours by Competency (auto-calculated from your X marks below): | G3: =SUMIF($G$6:$G$200,"X",$F$6:$F$200) | H3: =SUMIF($H$6:$H$200,"X",$F$6:$F$200) | I3: =SUMIF($I$6:$I$200,"X",$F$6:$F$200) | J3: =SUMIF($J$6:$J$200,"X",$F$6:$F$200) | K3: =SUMIF($K$6:$K$200,"X",$F$6:$F$200) | L3: =SUMIF($L$6:$L$200,"X",$F$6:$F$200) | M3: ← Competency hour totals
A5: Type | B5: Date | C5: Location | D5: Role | E5: Experience Description | F5: Hrs | G5: ① | H5: ② | I5: ③ | J5: ④ | K5: ⑤ | L5: ⑥ | M5: Evidence / Notes | N5: Site name | O5: Completed
A6: EMBEDDED | B6: 46189 | C6: Agency | D6: Participant | E6: Embedded Experience: Create a School-Community Profile: Work with school stakeholders (families, caregivers, and community members) to identify emerging trends and issues within the school community. Analyze the data collected and present findings to the school leadership team. | F6: 10 | J6: X | M6: Submit: Class Assignment | O6: Yes
A7: ALIGNED | B7: 46190 | C7: Agency | D7: Participant | E7: Aligned Experience: Interview someone from an agency concerning its relationship with schools or the school division. | F7: 5 | J7: X | M7: Submit: Competency Journal 4 | O7: Yes
A8: ALIGNED | B8: 46191 | C8: Agency | D8: Participant | E8: Aligned Experience: Conduct a Technology Audit to Assess Communication Accessibility for Stakeholders. | F8: 5 | J8: X | M8: Submit: Audit Report | O8: Yes
A9: ⭐ CHOICE HOURS — 12 hours needed this semester | E9: =IF(SUMIF(A10:A59,"CHOICE",F10:F59)>=12,"✅ Choice Hours Met!","⚠ Still need: "&(12-SUMIF(A10:A59,"CHOICE",F10:F59))&" more hours") | G9: 1. I | H9: 2. O | I9: 3. O | J9: 4. S | K9: 5. P | L9: 6. A | M9: No evidence required for choice hours
A10: CHOICE | B10: 46209 | C10: High | D10: Leader | E10: Facilitated a staff data meeting with the assistant principal and drafted a one-page summary of next steps | F10: 3 | K10: X | O10: Yes
A11: CHOICE | B11: 46212 | C11: Elementary | D11: Participant | E11: Worked with the PTA president to plan a family night and wrote a reflection on community engagement barriers | F11: 3 | J11: X | O11: Yes
A12: CHOICE | B12: 46217 | C12: Central Office | D12: Observer | E12: Observed a district budget work session and wrote notes connecting decisions to school priorities | F12: 3 | I12: X | O12: Yes
A13: CHOICE
A14: CHOICE
A15: CHOICE
A16: CHOICE
A17: CHOICE
A18: CHOICE
A19: CHOICE
A20: CHOICE
A21: CHOICE
A22: CHOICE
A23: CHOICE
A24: CHOICE
... A31: CHOICE

Sheet 7812
A1: INTERNSHIP LOG | 7812 – Leading Continuous Improvement | Semester 1
A2: Name: Pat Example Placement(s): Invented Elementary | E2: Total Hours Logged | G2: =SUM(F6:F200) | H2: Remaining | J2: =(32-G2)
A3: Hours by Competency (auto-calculated from your X marks below): | G3: =SUMIF($G$6:$G$200,"X",$F$6:$F$200) | H3: =SUMIF($H$6:$H$200,"X",$F$6:$F$200) | I3: =SUMIF($I$6:$I$200,"X",$F$6:$F$200) | J3: =SUMIF($J$6:$J$200,"X",$F$6:$F$200) | K3: =SUMIF($K$6:$K$200,"X",$F$6:$F$200) | L3: =SUMIF($L$6:$L$200,"X",$F$6:$F$200) | M3: ← Competency hour totals
A5: Type | B5: Date | C5: Location | D5: Role | E5: Experience Description | F5: Hrs | G5: ① | H5: ② | I5: ③ | J5: ④ | K5: ⑤ | L5: ⑥ | M5: Evidence / Notes | N5: Site name | O5: Completed
A6: EMBEDDED | B6: 46189 | C6: Middle | D6: Participant | E6: Embedded Experience: Continuous Improvement Semester Plan: As team leader of improvement in your school, you will prepare for a short-cycle improvement cycle targeting your selected area of instructional improvement by developing a slideshow that describes your Project Charter. | F6: 15 | H6: X | M6: Submit: Assignment | O6: Yes
A7: ALIGNED | B7: 46190 | C7: Middle | D7: Participant | E7: Aligned Experience: Obtain a copy of the School Improvement Plan for your school. Debrief with a school leader about decision-making related to the SIP. | F7: 5 | H7: X | M7: Submit: Agenda and Meeting Notes | O7: Yes
A8: ALIGNED | B8: 46191 | C8: Middle | D8: Participant | E8: Aligned Experience: Participate in discussions aimed at reaching a consensus on a school issue (e.g., grading policy, behavior support). | F8: 5 | H8: X | M8: Submit: Notes Taken from Meeting | O8: Yes
A9: ⭐ CHOICE HOURS — 7 hours needed this semester | E9: =IF(SUMIF(A10:A59,"CHOICE",F10:F59)>=7,"✅ Choice Hours Met!","⚠ Still need: "&(7-SUMIF(A10:A59,"CHOICE",F10:F59))&" more hours") | G9: 1. I | H9: 2. O | I9: 3. O | J9: 4. S | K9: 5. P | L9: 6. A | M9: No evidence required for choice hours
A10: CHOICE | B10: 46209 | C10: High | D10: Leader | E10: Led a grade-level team through an improvement-cycle review with the principal and recorded recommendations | F10: 3 | K10: X | O10: Yes
A11: CHOICE | B11: 46212 | C11: Elementary | D11: Participant | E11: Interviewed two community partners about school outreach and summarized findings for the leadership team | F11: 3 | J11: X | O11: Yes
A12: CHOICE | B12: 46217 | C12: Central Office | D12: Observer | E12: Shadowed the transportation director during bus route planning and reflected on operational tradeoffs | F12: 3 | I12: X | O12: Yes
A13: CHOICE
A14: CHOICE
A15: CHOICE
A16: CHOICE
A17: CHOICE
A18: CHOICE
A19: CHOICE
A20: CHOICE
A21: CHOICE
A22: CHOICE
A23: CHOICE
A24: CHOICE
... A31: CHOICE

Sheet 7811
A1: INTERNSHIP LOG | 7811 – Teaching & Learning | Semester 2
A2: Name: Pat Example Placement(s): Invented Elementary | E2: Total Hours Logged | G2: =SUM(F6:F200) | H2: Remaining | J2: =(32-G2)
A3: Hours by Competency (auto-calculated from your X marks below): | G3: =SUMIF($G$6:$G$200,"X",$F$6:$F$200) | H3: =SUMIF($H$6:$H$200,"X",$F$6:$F$200) | I3: =SUMIF($I$6:$I$200,"X",$F$6:$F$200) | J3: =SUMIF($J$6:$J$200,"X",$F$6:$F$200) | K3: =SUMIF($K$6:$K$200,"X",$F$6:$F$200) | L3: =SUMIF($L$6:$L$200,"X",$F$6:$F$200) | M3: ← Competency hour totals
A5: Type | B5: Date | C5: Location | D5: Role | E5: Experience Description | F5: Hrs | G5: ① | H5: ② | I5: ③ | J5: ④ | K5: ⑤ | L5: ⑥ | M5: Evidence / Notes | N5: Site name | O5: Completed
A6: EMBEDDED | C6: Main Site | E6: Embedded Experience: Observation-Feedback Experience: Practice an aspect of instructional supervision. You and your mentor will visit a classroom together to observe a teacher and provide structured feedback. | F6: 15 | G6: X | M6: Submit: Assignment
A7: ALIGNED | E7: Aligned Experience: Enhance your knowledge, understanding, and application of Virginia's school leader competencies through mentor-guided fieldwork. | F7: 5 | H7: X | M7: Submit: Competency Journal #2
A8: ALIGNED | E8: Aligned Experience: Plan and Conduct a Needs Assessment: Design a simple needs assessment to identify gaps in instructional resources or support that affect student outcomes. | F8: 5 | G8: X | M8: Submit: Needs Assessment Report
A9: ⭐ CHOICE HOURS — 7 hours needed this semester | E9: =IF(SUMIF(A10:A59,"CHOICE",F10:F59)>=7,"✅ Choice Hours Met!","⚠ Still need: "&(7-SUMIF(A10:A59,"CHOICE",F10:F59))&" more hours") | G9: 1. I | H9: 2. O | I9: 3. O | J9: 4. S | K9: 5. P | L9: 6. A | M9: No evidence required for choice hours
A10: CHOICE
A11: CHOICE
A12: CHOICE
A13: CHOICE
A14: CHOICE
A15: CHOICE
A16: CHOICE
A17: CHOICE
A18: CHOICE
A19: CHOICE
A20: CHOICE
A21: CHOICE
... A27: CHOICE

Sheet 7807
A1: INTERNSHIP LOG | 7807 – Leadership I | Semester 2
A2: Name: Pat Example Placement(s): Invented Elementary | E2: Total Hours Logged | G2: =SUM(F6:F200) | H2: Remaining | J2: =(32-G2)
A3: Hours by Competency (auto-calculated from your X marks below): | G3: =SUMIF($G$6:$G$200,"X",$F$6:$F$200) | H3: =SUMIF($H$6:$H$200,"X",$F$6:$F$200) | I3: =SUMIF($I$6:$I$200,"X",$F$6:$F$200) | J3: =SUMIF($J$6:$J$200,"X",$F$6:$F$200) | K3: =SUMIF($K$6:$K$200,"X",$F$6:$F$200) | L3: =SUMIF($L$6:$L$200,"X",$F$6:$F$200) | M3: ← Competency hour totals
A5: Type | B5: Date | C5: Location | D5: Role | E5: Experience Description | F5: Hrs | G5: ① | H5: ② | I5: ③ | J5: ④ | K5: ⑤ | L5: ⑥ | M5: Evidence / Notes | N5: Site name | O5: Completed
A6: EMBEDDED | C6: Main Site | E6: Embedded Experience: Conduct a modified 90-day inquiry cycle: Create a 90-day inquiry cycle targeting a problem of practice in your school. Analyze data, identify root causes, and develop an action plan. | F6: 25 | H6: X | M6: Submit: Class Assignment
A7: ALIGNED | E7: Aligned Experience: Reflect on a Decision with your mentor: Interns must learn to reflect on their decisions and have conversations with trusted colleagues about the decision itself and the process used in making the decision. | F7: 5 | K7: X | M7: Submit: Journal – Competency 5
A8: ⭐ CHOICE HOURS — 2 hours needed this semester | E8: =IF(SUMIF(A9:A58,"CHOICE",F9:F58)>=2,"✅ Choice Hours Met!","⚠ Still need: "&(2-SUMIF(A9:A58,"CHOICE",F9:F58))&" more hours") | G8: 1. I | H8: 2. O | I8: 3. O | J8: 4. S | K8: 5. P | L8: 6. A | M8: No evidence required for choice hours
A9: CHOICE
A10: CHOICE
A11: CHOICE
A12: CHOICE
A13: CHOICE
A14: CHOICE
A15: CHOICE
A16: CHOICE
A17: CHOICE
A18: CHOICE
A19: CHOICE
A20: CHOICE
... A28: CHOICE

Sheet 7810
A1: INTERNSHIP LOG | 7810 – School Law & Policy | Semester 3
A2: Name: Pat Example Placement(s): Invented Elementary | E2: Total Hours Logged | G2: =SUM(F6:F200) | H2: Remaining | J2: =(32-G2)
A3: Hours by Competency (auto-calculated from your X marks below): | G3: =SUMIF($G$6:$G$200,"X",$F$6:$F$200) | H3: =SUMIF($H$6:$H$200,"X",$F$6:$F$200) | I3: =SUMIF($I$6:$I$200,"X",$F$6:$F$200) | J3: =SUMIF($J$6:$J$200,"X",$F$6:$F$200) | K3: =SUMIF($K$6:$K$200,"X",$F$6:$F$200) | L3: =SUMIF($L$6:$L$200,"X",$F$6:$F$200) | M3: ← Competency hour totals
A5: Type | B5: Date | C5: Location | D5: Role | E5: Experience Description | F5: Hrs | G5: ① | H5: ② | I5: ③ | J5: ④ | K5: ⑤ | L5: ⑥ | M5: Evidence / Notes | N5: Site name | O5: Completed
A6: EMBEDDED | C6: Main Site | E6: Embedded Experience: Contemporary Issues: Planning and Debate: Select a contemporary educational law or policy issue. Research both sides, develop a position paper, and participate in a structured debate. | F6: 10 | L6: X | M6: Submit: Assignment
A7: ALIGNED | E7: Aligned Experience: Attend a School Board Meeting to Observe Policy Development: Observe how school board members discuss and vote on policy issues. | F7: 5 | L7: X | M7: Submit: Competency Journal 6
A8: ALIGNED | E8: Aligned Experience: Shadow an Administrator During a Disciplinary Hearing: Observe the processes and legal considerations involved in a student disciplinary hearing. | F8: 5 | K8: X | M8: Submit: Observation Notes
A9: ⭐ CHOICE HOURS — 12 hours needed this semester | E9: =IF(SUMIF(A10:A59,"CHOICE",F10:F59)>=12,"✅ Choice Hours Met!","⚠ Still need: "&(12-SUMIF(A10:A59,"CHOICE",F10:F59))&" more hours") | G9: 1. I | H9: 2. O | I9: 3. O | J9: 4. S | K9: 5. P | L9: 6. A | M9: No evidence required for choice hours
A10: CHOICE
A11: CHOICE
A12: CHOICE
A13: CHOICE
A14: CHOICE
A15: CHOICE
A16: CHOICE
A17: CHOICE
A18: CHOICE
A19: CHOICE
A20: CHOICE
A21: CHOICE
... A31: CHOICE

Sheet 7140
A1: INTERNSHIP LOG | 7140 – Leadership II (LEAD II) | Semester 3
A2: Name: Pat Example Placement(s): Invented Elementary | E2: Total Hours Logged | G2: =SUM(F6:F200) | H2: Remaining | J2: =(32-G2)
A3: Hours by Competency (auto-calculated from your X marks below): | G3: =SUMIF($G$6:$G$200,"X",$F$6:$F$200) | H3: =SUMIF($H$6:$H$200,"X",$F$6:$F$200) | I3: =SUMIF($I$6:$I$200,"X",$F$6:$F$200) | J3: =SUMIF($J$6:$J$200,"X",$F$6:$F$200) | K3: =SUMIF($K$6:$K$200,"X",$F$6:$F$200) | L3: =SUMIF($L$6:$L$200,"X",$F$6:$F$200) | M3: ← Competency hour totals
A5: Type | B5: Date | C5: Location | D5: Role | E5: Experience Description | F5: Hrs | G5: ① | H5: ② | I5: ③ | J5: ④ | K5: ⑤ | L5: ⑥ | M5: Evidence / Notes | N5: Site name | O5: Completed
A6: EMBEDDED | C6: Main Site | E6: Embedded Experience: Performance Assessment – Field-based Learning Application: This performance assessment is organized as a highly structured Field-based Learning Application that becomes your Field-based Learning Application Report upon its final submission. | F6: 25 | G6: X | M6: Submit: Assignment
A7: ALIGNED | E7: Aligned Experience: Serve as principal for a half/full day and/or shadow a principal noting and reflecting on all or several of the dispositions outlined in the competency components. | F7: 5 | K7: X | M7: Submit: Timeline
A8: ⭐ CHOICE HOURS — 2 hours needed this semester | E8: =IF(SUMIF(A9:A58,"CHOICE",F9:F58)>=2,"✅ Choice Hours Met!","⚠ Still need: "&(2-SUMIF(A9:A58,"CHOICE",F9:F58))&" more hours") | G8: 1. I | H8: 2. O | I8: 3. O | J8: 4. S | K8: 5. P | L8: 6. A | M8: No evidence required for choice hours
A9: CHOICE
A10: CHOICE
A11: CHOICE
A12: CHOICE
A13: CHOICE
A14: CHOICE
A15: CHOICE
A16: CHOICE
A17: CHOICE
A18: CHOICE
A19: CHOICE
A20: CHOICE
... A31: CHOICE

Sheet 7808
A1: INTERNSHIP LOG | 7808 – School Finance | Semester 4
A2: Name: Pat Example Placement(s): Invented Elementary | E2: Total Hours Logged | G2: =SUM(F6:F200) | H2: Remaining | J2: =(32-G2)
A3: Hours by Competency (auto-calculated from your X marks below): | G3: =SUMIF($G$6:$G$200,"X",$F$6:$F$200) | H3: =SUMIF($H$6:$H$200,"X",$F$6:$F$200) | I3: =SUMIF($I$6:$I$200,"X",$F$6:$F$200) | J3: =SUMIF($J$6:$J$200,"X",$F$6:$F$200) | K3: =SUMIF($K$6:$K$200,"X",$F$6:$F$200) | L3: =SUMIF($L$6:$L$200,"X",$F$6:$F$200) | M3: ← Competency hour totals
A5: Type | B5: Date | C5: Location | D5: Role | E5: Experience Description | F5: Hrs | G5: ① | H5: ② | I5: ③ | J5: ④ | K5: ⑤ | L5: ⑥ | M5: Evidence / Notes | N5: Site name | O5: Completed
A6: EMBEDDED | B6: 46279 | C6: Main Site | D6: Participant | E6: Embedded Experience: Budget Analysis Project – Case Study #4: Building a School Budget. Develop a comprehensive school budget using real-world data and present it to a mock school board. | F6: 15 | I6: X | M6: Submit: Assignment | O6: Yes
A7: ALIGNED | B7: 46293 | C7: Main Site | D7: Participant | E7: Aligned Experience: School Improvement Collaboration: Work with the school improvement team to align resources (staffing, time, materials) with student achievement goals. | F7: 5 | J7: X | M7: Submit: Resource Alignment Plan | O7: Yes
A8: ALIGNED | E8: Aligned Experience: Review programs and practices for equity, fairness, and respect, and develop recommendations for improvement. | F8: 5 | K8: X | M8: Submit: Resource Evaluation Report
A9: ⭐ CHOICE HOURS — 7 hours needed this semester | E9: =IF(SUMIF(A10:A59,"CHOICE",F10:F59)>=7,"✅ Choice Hours Met!","⚠ Still need: "&(7-SUMIF(A10:A59,"CHOICE",F10:F59))&" more hours") | G9: 1. I | H9: 2. O | I9: 3. O | J9: 4. S | K9: 5. P | L9: 6. A | M9: No evidence required for choice hours
A10: CHOICE | B10: 46300 | C10: Elementary | D10: Leader | E10: Help with budget | F10: 2 | I10: X | O10: Yes
A11: CHOICE | B11: 46303 | C11: Central Office | D11: Observer | E11: Lead a culture change initiative for the whole school with the leadership team and create an action plan | F11: 3 | K11: X | O11: Yes
A12: CHOICE | B12: 46307 | C12: Middle | D12: Participant | E12: Attended finance committee | F12: 4 | L12: X
A13: CHOICE | E13: Copy and paste choice hours here. No activity may be more than three hours
A14: CHOICE
A15: CHOICE
A16: CHOICE
A17: CHOICE
A18: CHOICE
A19: CHOICE
A20: CHOICE
A21: CHOICE
A22: CHOICE
A23: CHOICE
A24: CHOICE
A25: CHOICE
... A31: CHOICE

Sheet 7805
A1: INTERNSHIP LOG | 7805 – Cultivating Professional Capacity | Semester 4
A2: Name: Pat Example Placement(s): Invented Elementary | E2: Total Hours Logged | G2: =SUM(F6:F200) | H2: Remaining | J2: =(32-G2)
A3: Hours by Competency (auto-calculated from your X marks below): | G3: =SUMIF($G$6:$G$200,"X",$F$6:$F$200) | H3: =SUMIF($H$6:$H$200,"X",$F$6:$F$200) | I3: =SUMIF($I$6:$I$200,"X",$F$6:$F$200) | J3: =SUMIF($J$6:$J$200,"X",$F$6:$F$200) | K3: =SUMIF($K$6:$K$200,"X",$F$6:$F$200) | L3: =SUMIF($L$6:$L$200,"X",$F$6:$F$200) | M3: ← Competency hour totals
A5: Type | B5: Date | C5: Location | D5: Role | E5: Experience Description | F5: Hrs | G5: ① | H5: ② | I5: ③ | J5: ④ | K5: ⑤ | L5: ⑥ | M5: Evidence / Notes | N5: Site name | O5: Completed
A6: EMBEDDED | C6: Main Site | E6: Embedded Experience: HR Roadmap – Capacity Roadmap: A cumulative project developed throughout the course focused on building and sustaining human capital capacity in your school or division. | F6: 15 | K6: X | M6: Submit: Assignment
A7: ALIGNED | E7: Aligned Experience: Participate in/observe the hiring of a teacher, instructional coach, or school instructional support professional. | F7: 5 | I7: X | M7: Submit: Journal – Competency 3
A8: ALIGNED | E8: Aligned Experience: Interview or Shadow a Non-Instructional Leader: Interview or shadow a non-instructional leader to understand their role in supporting school operations. | F8: 5 | I8: X | M8: Submit: Interview or Observation Notes
A9: ⭐ CHOICE HOURS — 7 hours needed this semester | E9: =IF(SUMIF(A10:A59,"CHOICE",F10:F59)>=7,"✅ Choice Hours Met!","⚠ Still need: "&(7-SUMIF(A10:A59,"CHOICE",F10:F59))&" more hours") | G9: 1. I | H9: 2. O | I9: 3. O | J9: 4. S | K9: 5. P | L9: 6. A | M9: No evidence required for choice hours
A10: CHOICE
A11: CHOICE
A12: CHOICE
A13: CHOICE
A14: CHOICE
A15: CHOICE
A16: CHOICE
A17: CHOICE
A18: CHOICE
A19: CHOICE
A20: CHOICE
A21: CHOICE
... A29: CHOICE

Sheet 7813
A1: INTERNSHIP LOG | 7813 – Educational Technology | Semester 5
A2: Name: Pat Example Placement(s): Invented Elementary | E2: Total Hours Logged | G2: =SUM(F6:F200) | H2: Remaining | J2: =(32-G2)
A3: Hours by Competency (auto-calculated from your X marks below): | G3: =SUMIF($G$6:$G$200,"X",$F$6:$F$200) | H3: =SUMIF($H$6:$H$200,"X",$F$6:$F$200) | I3: =SUMIF($I$6:$I$200,"X",$F$6:$F$200) | J3: =SUMIF($J$6:$J$200,"X",$F$6:$F$200) | K3: =SUMIF($K$6:$K$200,"X",$F$6:$F$200) | L3: =SUMIF($L$6:$L$200,"X",$F$6:$F$200) | M3: ← Competency hour totals
A5: Type | B5: Date | C5: Location | D5: Role | E5: Experience Description | F5: Hrs | G5: ① | H5: ② | I5: ③ | J5: ④ | K5: ⑤ | L5: ⑥ | M5: Evidence / Notes | N5: Site name | O5: Completed
A6: EMBEDDED | B6: 46303 | C6: Main Site | D6: Participant | E6: Embedded Experience: System of Practice for the Leadership of Technology: Assess leadership practices for technology integration in your school. Develop a technology leadership action plan aligned to school improvement goals. | F6: 20 | J6: X | M6: Submit: Assignment | O6: Yes
A7: ALIGNED | B7: 46304 | C7: Main Site | D7: Participant | E7: Aligned Experience: Technology Integration: Assist in integrating technology into lesson planning and delivery by collaborating with teachers to design tech-enhanced lessons. | F7: 5 | J7: X | M7: Submit: Lesson Plans | O7: Yes
A8: ALIGNED | B8: 46305 | C8: Main Site | D8: Participant | E8: Aligned Experience: Digital Resource Audit: Conduct an audit of current technology resources available in your school and assess their alignment with instructional goals. | F8: 5 | I8: X | M8: Submit: Audit Report
A9: ⭐ CHOICE HOURS — 2 hours needed this semester | E9: =IF(SUMIF(A10:A59,"CHOICE",F10:F59)>=2,"✅ Choice Hours Met!","⚠ Still need: "&(2-SUMIF(A10:A59,"CHOICE",F10:F59))&" more hours") | G9: 1. I | H9: 2. O | I9: 3. O | J9: 4. S | K9: 5. P | L9: 6. A | M9: No evidence required for choice hours
A10: CHOICE | B10: 46346 | C10: High | D10: Participant | E10: Lead a culture change initiative for the whole school with the leadership team and create an action plan | F10: 2 | K10: X
A11: CHOICE | E11: Copy and paste choice hours here. No activity may be more than three hours
A12: CHOICE | B12: 46320 | C12: Middle | D12: Participant | E12: Instructional Technology PD: Organize and lead a professional development session on tech. (VDOE 1,3,4) | F12: 1 | G12: X
A13: CHOICE
A14: CHOICE
A15: CHOICE
A16: CHOICE
A17: CHOICE
A18: CHOICE
A19: CHOICE
A20: CHOICE
A21: CHOICE
A22: CHOICE
A23: CHOICE
A24: CHOICE
... A30: CHOICE

Sheet 7815
A1: INTERNSHIP LOG | 7815 – Leadership for Diverse Learners | Semester 5
A2: Name: Pat Example Placement(s): Invented Elementary | E2: Total Hours Logged | G2: =SUM(F6:F200) | H2: Remaining | J2: =(32-G2)
A3: Hours by Competency (auto-calculated from your X marks below): | G3: =SUMIF($G$6:$G$200,"X",$F$6:$F$200) | H3: =SUMIF($H$6:$H$200,"X",$F$6:$F$200) | I3: =SUMIF($I$6:$I$200,"X",$F$6:$F$200) | J3: =SUMIF($J$6:$J$200,"X",$F$6:$F$200) | K3: =SUMIF($K$6:$K$200,"X",$F$6:$F$200) | L3: =SUMIF($L$6:$L$200,"X",$F$6:$F$200) | M3: ← Competency hour totals
A5: Type | B5: Date | C5: Location | D5: Role | E5: Experience Description | F5: Hrs | G5: ① | H5: ② | I5: ③ | J5: ④ | K5: ⑤ | L5: ⑥ | M5: Evidence / Notes | N5: Site name | O5: Completed
A6: EMBEDDED | E6: Embedded Experience: Final Group Project on Social Justice Advocacy: This collaborative assignment asks you to develop and present an advocacy plan addressing a systemic equity issue in your school or division. | F6: 10 | L6: X | M6: Submit: Assignment
A7: ALIGNED | E7: Aligned Experience: Shadow a Special Education Leader: Shadow and interview a division or school-based special education leader to understand their role, responsibilities, and challenges. | F7: 5 | G7: X | M7: Submit: Journal – Competency 1
A8: ALIGNED | E8: Aligned Experience: Oversee or observe an IEP or RTI meeting with support from the school administrator. | F8: 5 | L8: X | M8: Submit: Meeting Observation Form
A9: ⭐ CHOICE HOURS — 12 hours needed this semester | E9: =IF(SUMIF(A10:A59,"CHOICE",F10:F59)>=12,"✅ Choice Hours Met!","⚠ Still need: "&(12-SUMIF(A10:A59,"CHOICE",F10:F59))&" more hours") | G9: 1. I | H9: 2. O | I9: 3. O | J9: 4. S | K9: 5. P | L9: 6. A | M9: No evidence required for choice hours
A10: CHOICE
A11: CHOICE
A12: CHOICE
A13: CHOICE
A14: CHOICE
A15: CHOICE
A16: CHOICE
A17: CHOICE
A18: CHOICE
A19: CHOICE
A20: CHOICE
A21: CHOICE
... A28: CHOICE

Sheet 📊 Dashboard
A1: 📊 INTERNSHIP PROGRESS DASHBOARD
A3: OVERALL HOURS PROGRESS (Goal: 320 hours across 5 semesters)
B4: Planned Hours | C4: Target Hours | D4: Remaining for CHOICE
A5: 7806 – School & Community Relations | B5: ='7806'!G2 | C5: 32 | D5: =C5-B5
A6: 7812 – Leading Continuous Improvement | B6: ='7812'!G2 | C6: 32 | D6: =C6-B6
A7: 7811 – Teaching & Learning | B7: ='7811'!G2 | C7: 32 | D7: =C7-B7
A8: 7807 – Leadership I | B8: ='7807'!G2 | C8: 32 | D8: =C8-B8
A9: 7810 – School Law & Policy | B9: ='7810'!G2 | C9: 32 | D9: =C9-B9
A10: 7140 – Leadership II (LEAD II) | B10: ='7140'!G2 | C10: 32 | D10: =C10-B10
A11: 7808 – School Finance | B11: ='7808'!G2 | C11: 32 | D11: =C11-B11
A12: 7805 – Cultivating Professional Capacity | B12: ='7805'!G2 | C12: 32 | D12: =C12-B12
A13: 7813 – Educational Technology | B13: ='7813'!G2 | C13: 32 | D13: =C13-B13
A14: 7815 – Leadership for Diverse Learners | B14: ='7815'!G2 | C14: 32 | D14: =C14-B14
A15: TOTAL | B15: =SUM(B5:B14) | C15: =SUM(C5:C14) | D15: =C15-B15
A17: HOURS BY COMPETENCY (across all courses — Choice hours only)
A18: Competency | B18: Choice Hours Logged | C18: Min Required | D18: Remaining
A19: 1. Instructional Leadership | B19: =SUMIFS('7806'!$F$6:$F$200,'7806'!$A$6:$A$200,"CHOICE",'7806'!G$6:G$200,"X")+SUMIFS('7812'!$F$6:$F$200,'7812'!$A$6:$A$200,"CHOICE",'7812'!G$6:G$200,"X")+SUMIFS('7811'!$F$6:$F$200,'7811'!$A$6:$A$200,"CHOICE",'7811'!G$6:G$200,"X")+SUMIFS('7807'!$F$6:$F$200,'7807'!$A$6:$A$200,"CHOICE",'7807'!G$6:G$200,"X")+SUMIFS('7810'!$F$6:$F$200,'7810'!$A$6:$A$200,"CHOICE",'7810'!G$6:G$200,"X")+SUMIFS('7140'!$F$6:$F$200,'7140'!$A$6:$A$200,"CHOICE",'7140'!G$6:G$200,"X")+SUMIFS('7808'!$F$6:$F$200,'7808'!$A$6:$A$200,"CHOICE",'7808'!G$6:G$200,"X")+SUMIFS('7805'!$F$6:$F$200,'7805'!$A$6:$A$200,"CHOICE",'7805'!G$6:G$200,"X")+SUMIFS('7813'!$F$6:$F$200,'7813'!$A$6:$A$200,"CHOICE",'7813'!G$6:G$200,"X")+SUMIFS('7815'!$F$6:$F$200,'7815'!$A$6:$A$200,"CHOICE",'7815'!G$6:G$200,"X") | C19: 3 | D19: =MAX(0,C19-B19)
A20: 2. Organizational Management | B20: =SUMIFS('7806'!$F$6:$F$200,'7806'!$A$6:$A$200,"CHOICE",'7806'!H$6:H$200,"X")+SUMIFS('7812'!$F$6:$F$200,'7812'!$A$6:$A$200,"CHOICE",'7812'!H$6:H$200,"X")+SUMIFS('7811'!$F$6:$F$200,'7811'!$A$6:$A$200,"CHOICE",'7811'!H$6:H$200,"X")+SUMIFS('7807'!$F$6:$F$200,'7807'!$A$6:$A$200,"CHOICE",'7807'!H$6:H$200,"X")+SUMIFS('7810'!$F$6:$F$200,'7810'!$A$6:$A$200,"CHOICE",'7810'!H$6:H$200,"X")+SUMIFS('7140'!$F$6:$F$200,'7140'!$A$6:$A$200,"CHOICE",'7140'!H$6:H$200,"X")+SUMIFS('7808'!$F$6:$F$200,'7808'!$A$6:$A$200,"CHOICE",'7808'!H$6:H$200,"X")+SUMIFS('7805'!$F$6:$F$200,'7805'!$A$6:$A$200,"CHOICE",'7805'!H$6:H$200,"X")+SUMIFS('7813'!$F$6:$F$200,'7813'!$A$6:$A$200,"CHOICE",'7813'!H$6:H$200,"X")+SUMIFS('7815'!$F$6:$F$200,'7815'!$A$6:$A$200,"CHOICE",'7815'!H$6:H$200,"X") | C20: 0 | D20: =MAX(0,C20-B20)
A21: 3. Operational Management | B21: =SUMIFS('7806'!$F$6:$F$200,'7806'!$A$6:$A$200,"CHOICE",'7806'!I$6:I$200,"X")+SUMIFS('7812'!$F$6:$F$200,'7812'!$A$6:$A$200,"CHOICE",'7812'!I$6:I$200,"X")+SUMIFS('7811'!$F$6:$F$200,'7811'!$A$6:$A$200,"CHOICE",'7811'!I$6:I$200,"X")+SUMIFS('7807'!$F$6:$F$200,'7807'!$A$6:$A$200,"CHOICE",'7807'!I$6:I$200,"X")+SUMIFS('7810'!$F$6:$F$200,'7810'!$A$6:$A$200,"CHOICE",'7810'!I$6:I$200,"X")+SUMIFS('7140'!$F$6:$F$200,'7140'!$A$6:$A$200,"CHOICE",'7140'!I$6:I$200,"X")+SUMIFS('7808'!$F$6:$F$200,'7808'!$A$6:$A$200,"CHOICE",'7808'!I$6:I$200,"X")+SUMIFS('7805'!$F$6:$F$200,'7805'!$A$6:$A$200,"CHOICE",'7805'!I$6:I$200,"X")+SUMIFS('7813'!$F$6:$F$200,'7813'!$A$6:$A$200,"CHOICE",'7813'!I$6:I$200,"X")+SUMIFS('7815'!$F$6:$F$200,'7815'!$A$6:$A$200,"CHOICE",'7815'!I$6:I$200,"X") | C21: 23 | D21: =MAX(0,C21-B21)
A22: 4. Systemic Equity & Community Engagement | B22: =SUMIFS('7806'!$F$6:$F$200,'7806'!$A$6:$A$200,"CHOICE",'7806'!J$6:J$200,"X")+SUMIFS('7812'!$F$6:$F$200,'7812'!$A$6:$A$200,"CHOICE",'7812'!J$6:J$200,"X")+SUMIFS('7811'!$F$6:$F$200,'7811'!$A$6:$A$200,"CHOICE",'7811'!J$6:J$200,"X")+SUMIFS('7807'!$F$6:$F$200,'7807'!$A$6:$A$200,"CHOICE",'7807'!J$6:J$200,"X")+SUMIFS('7810'!$F$6:$F$200,'7810'!$A$6:$A$200,"CHOICE",'7810'!J$6:J$200,"X")+SUMIFS('7140'!$F$6:$F$200,'7140'!$A$6:$A$200,"CHOICE",'7140'!J$6:J$200,"X")+SUMIFS('7808'!$F$6:$F$200,'7808'!$A$6:$A$200,"CHOICE",'7808'!J$6:J$200,"X")+SUMIFS('7805'!$F$6:$F$200,'7805'!$A$6:$A$200,"CHOICE",'7805'!J$6:J$200,"X")+SUMIFS('7813'!$F$6:$F$200,'7813'!$A$6:$A$200,"CHOICE",'7813'!J$6:J$200,"X")+SUMIFS('7815'!$F$6:$F$200,'7815'!$A$6:$A$200,"CHOICE",'7815'!J$6:J$200,"X") | C22: 4 | D22: =MAX(0,C22-B22)
A23: 5. Professionalism | B23: =SUMIFS('7806'!$F$6:$F$200,'7806'!$A$6:$A$200,"CHOICE",'7806'!K$6:K$200,"X")+SUMIFS('7812'!$F$6:$F$200,'7812'!$A$6:$A$200,"CHOICE",'7812'!K$6:K$200,"X")+SUMIFS('7811'!$F$6:$F$200,'7811'!$A$6:$A$200,"CHOICE",'7811'!K$6:K$200,"X")+SUMIFS('7807'!$F$6:$F$200,'7807'!$A$6:$A$200,"CHOICE",'7807'!K$6:K$200,"X")+SUMIFS('7810'!$F$6:$F$200,'7810'!$A$6:$A$200,"CHOICE",'7810'!K$6:K$200,"X")+SUMIFS('7140'!$F$6:$F$200,'7140'!$A$6:$A$200,"CHOICE",'7140'!K$6:K$200,"X")+SUMIFS('7808'!$F$6:$F$200,'7808'!$A$6:$A$200,"CHOICE",'7808'!K$6:K$200,"X")+SUMIFS('7805'!$F$6:$F$200,'7805'!$A$6:$A$200,"CHOICE",'7805'!K$6:K$200,"X")+SUMIFS('7813'!$F$6:$F$200,'7813'!$A$6:$A$200,"CHOICE",'7813'!K$6:K$200,"X")+SUMIFS('7815'!$F$6:$F$200,'7815'!$A$6:$A$200,"CHOICE",'7815'!K$6:K$200,"X") | C23: 23 | D23: =MAX(0,C23-B23)
A24: 6. Advocacy | B24: =SUMIFS('7806'!$F$6:$F$200,'7806'!$A$6:$A$200,"CHOICE",'7806'!L$6:L$200,"X")+SUMIFS('7812'!$F$6:$F$200,'7812'!$A$6:$A$200,"CHOICE",'7812'!L$6:L$200,"X")+SUMIFS('7811'!$F$6:$F$200,'7811'!$A$6:$A$200,"CHOICE",'7811'!L$6:L$200,"X")+SUMIFS('7807'!$F$6:$F$200,'7807'!$A$6:$A$200,"CHOICE",'7807'!L$6:L$200,"X")+SUMIFS('7810'!$F$6:$F$200,'7810'!$A$6:$A$200,"CHOICE",'7810'!L$6:L$200,"X")+SUMIFS('7140'!$F$6:$F$200,'7140'!$A$6:$A$200,"CHOICE",'7140'!L$6:L$200,"X")+SUMIFS('7808'!$F$6:$F$200,'7808'!$A$6:$A$200,"CHOICE",'7808'!L$6:L$200,"X")+SUMIFS('7805'!$F$6:$F$200,'7805'!$A$6:$A$200,"CHOICE",'7805'!L$6:L$200,"X")+SUMIFS('7813'!$F$6:$F$200,'7813'!$A$6:$A$200,"CHOICE",'7813'!L$6:L$200,"X")+SUMIFS('7815'!$F$6:$F$200,'7815'!$A$6:$A$200,"CHOICE",'7815'!L$6:L$200,"X") | C24: 17 | D24: =MAX(0,C24-B24)
A27: 📍 LOCATION REQUIREMENT: At least 50 hours must be completed outside your own building (min. 12.5 per site type)
A30: 📍 EXTERNAL HOURS TRACKER (Requirement: 50 hrs outside your building | min. 12.5 per site type)
A31: Enter your location in column C of each course tab using the dropdown. 'Main Site' = your own building and is excluded from external totals.
A32: Location Type | B32: Hours Logged | C32: Minimum Required | D32: Still Needed
A33: Elementary | B33: =IFERROR(SUMIF('7806'!C6:C200,"Elementary",('7806'!F6:F200)),0)+IFERROR(SUMIF('7812'!C6:C200,"Elementary",('7812'!F6:F200)),0)+IFERROR(SUMIF('7811'!C6:C200,"Elementary",('7811'!F6:F200)),0)+IFERROR(SUMIF('7807'!C6:C200,"Elementary",('7807'!F6:F200)),0)+IFERROR(SUMIF('7810'!C6:C200,"Elementary",('7810'!F6:F200)),0)+IFERROR(SUMIF('7140'!C6:C200,"Elementary",('7140'!F6:F200)),0)+IFERROR(SUMIF('7808'!C6:C200,"Elementary",('7808'!F6:F200)),0)+IFERROR(SUMIF('7805'!C6:C200,"Elementary",('7805'!F6:F200)),0)+IFERROR(SUMIF('7813'!C6:C200,"Elementary",('7813'!F6:F200)),0)+IFERROR(SUMIF('7815'!C6:C200,"Elementary",('7815'!F6:F200)),0) | C33: 12.5 | D33: =IF(B33>=12.5,"✅ Met","⚠ "&TEXT(MAX(0,12.5-B33),"0.0")&" hrs needed")
A34: Middle | B34: =IFERROR(SUMIF('7806'!C6:C200,"Middle",('7806'!F6:F200)),0)+IFERROR(SUMIF('7812'!C6:C200,"Middle",('7812'!F6:F200)),0)+IFERROR(SUMIF('7811'!C6:C200,"Middle",('7811'!F6:F200)),0)+IFERROR(SUMIF('7807'!C6:C200,"Middle",('7807'!F6:F200)),0)+IFERROR(SUMIF('7810'!C6:C200,"Middle",('7810'!F6:F200)),0)+IFERROR(SUMIF('7140'!C6:C200,"Middle",('7140'!F6:F200)),0)+IFERROR(SUMIF('7808'!C6:C200,"Middle",('7808'!F6:F200)),0)+IFERROR(SUMIF('7805'!C6:C200,"Middle",('7805'!F6:F200)),0)+IFERROR(SUMIF('7813'!C6:C200,"Middle",('7813'!F6:F200)),0)+IFERROR(SUMIF('7815'!C6:C200,"Middle",('7815'!F6:F200)),0) | C34: 12.5 | D34: =IF(B34>=12.5,"✅ Met","⚠ "&TEXT(MAX(0,12.5-B34),"0.0")&" hrs needed")
A35: High | B35: =IFERROR(SUMIF('7806'!C6:C200,"High",('7806'!F6:F200)),0)+IFERROR(SUMIF('7812'!C6:C200,"High",('7812'!F6:F200)),0)+IFERROR(SUMIF('7811'!C6:C200,"High",('7811'!F6:F200)),0)+IFERROR(SUMIF('7807'!C6:C200,"High",('7807'!F6:F200)),0)+IFERROR(SUMIF('7810'!C6:C200,"High",('7810'!F6:F200)),0)+IFERROR(SUMIF('7140'!C6:C200,"High",('7140'!F6:F200)),0)+IFERROR(SUMIF('7808'!C6:C200,"High",('7808'!F6:F200)),0)+IFERROR(SUMIF('7805'!C6:C200,"High",('7805'!F6:F200)),0)+IFERROR(SUMIF('7813'!C6:C200,"High",('7813'!F6:F200)),0)+IFERROR(SUMIF('7815'!C6:C200,"High",('7815'!F6:F200)),0) | C35: 12.5 | D35: =IF(B35>=12.5,"✅ Met","⚠ "&TEXT(MAX(0,12.5-B35),"0.0")&" hrs needed")
A36: Central Office | B36: =IFERROR(SUMIF('7806'!C6:C200,"Central Office",('7806'!F6:F200)),0)+IFERROR(SUMIF('7812'!C6:C200,"Central Office",('7812'!F6:F200)),0)+IFERROR(SUMIF('7811'!C6:C200,"Central Office",('7811'!F6:F200)),0)+IFERROR(SUMIF('7807'!C6:C200,"Central Office",('7807'!F6:F200)),0)+IFERROR(SUMIF('7810'!C6:C200,"Central Office",('7810'!F6:F200)),0)+IFERROR(SUMIF('7140'!C6:C200,"Central Office",('7140'!F6:F200)),0)+IFERROR(SUMIF('7808'!C6:C200,"Central Office",('7808'!F6:F200)),0)+IFERROR(SUMIF('7805'!C6:C200,"Central Office",('7805'!F6:F200)),0)+IFERROR(SUMIF('7813'!C6:C200,"Central Office",('7813'!F6:F200)),0)+IFERROR(SUMIF('7815'!C6:C200,"Central Office",('7815'!F6:F200)),0) | C36: 12.5 | D36: =IF(B36>=12.5,"✅ Met","⚠ "&TEXT(MAX(0,12.5-B36),"0.0")&" hrs needed")
A37: Agency | B37: =IFERROR(SUMIF('7806'!C6:C200,"Agency",('7806'!F6:F200)),0)+IFERROR(SUMIF('7812'!C6:C200,"Agency",('7812'!F6:F200)),0)+IFERROR(SUMIF('7811'!C6:C200,"Agency",('7811'!F6:F200)),0)+IFERROR(SUMIF('7807'!C6:C200,"Agency",('7807'!F6:F200)),0)+IFERROR(SUMIF('7810'!C6:C200,"Agency",('7810'!F6:F200)),0)+IFERROR(SUMIF('7140'!C6:C200,"Agency",('7140'!F6:F200)),0)+IFERROR(SUMIF('7808'!C6:C200,"Agency",('7808'!F6:F200)),0)+IFERROR(SUMIF('7805'!C6:C200,"Agency",('7805'!F6:F200)),0)+IFERROR(SUMIF('7813'!C6:C200,"Agency",('7813'!F6:F200)),0)+IFERROR(SUMIF('7815'!C6:C200,"Agency",('7815'!F6:F200)),0) | C37: 12.5 | D37: =IF(B37>=12.5,"✅ Met","⚠ "&TEXT(MAX(0,12.5-B37),"0.0")&" hrs needed")
A38: Other | B38: =IFERROR(SUMIF('7806'!C6:C200,"Other",('7806'!F6:F200)),0)+IFERROR(SUMIF('7812'!C6:C200,"Other",('7812'!F6:F200)),0)+IFERROR(SUMIF('7811'!C6:C200,"Other",('7811'!F6:F200)),0)+IFERROR(SUMIF('7807'!C6:C200,"Other",('7807'!F6:F200)),0)+IFERROR(SUMIF('7810'!C6:C200,"Other",('7810'!F6:F200)),0)+IFERROR(SUMIF('7140'!C6:C200,"Other",('7140'!F6:F200)),0)+IFERROR(SUMIF('7808'!C6:C200,"Other",('7808'!F6:F200)),0)+IFERROR(SUMIF('7805'!C6:C200,"Other",('7805'!F6:F200)),0)+IFERROR(SUMIF('7813'!C6:C200,"Other",('7813'!F6:F200)),0)+IFERROR(SUMIF('7815'!C6:C200,"Other",('7815'!F6:F200)),0) | C38: — | D38: —
A39: TOTAL EXTERNAL HOURS | B39: =SUM(B33:B38) | C39: 50 | D39: =IF(B39>=50,IF(COUNTIF(B33:B37,"<12.5")=0,"✅ Requirement Met!","✅ 50-hr total met, but "&COUNTIF(B33:B37,"<12.5")&" site type(s) are under 12.5 hrs"),"⚠ "&TEXT(MAX(0,50-B39),"0")&" more external hrs needed")

Sheet All CHOICE
A1: INTERN LOG: CHOICE HOURS | E1: Name: Date of Internship: Placements: | F1: Total Hours Logged | G1: =SUM(G6:G139) | H1: "SEMYR"when you add to PowerBI. I Suggest XSEMYR as you can easily cross reference the two documents by date.
A3: =MAX('CHOICE calc'!$E$2:$E$541)&" CHOICE entries found on your course tabs. A row is listed when it has a "&"description or hours."&IF(MAX('CHOICE calc'!$E$2:$E$541)>134," WARNING: only the first 134 are shown.","")
A5: Competency | B5: Date | C5: Name the Location | D5: Type | E5: Experience | F5: Role | G5: Hours | H5: Course
A6: =IFERROR(INDEX('CHOICE calc'!$F$2:$F$541,MATCH(ROWS(A$6:A6),'CHOICE calc'!$E$2:$E$541,0)),"") | B6: =IFERROR(INDEX('CHOICE calc'!$G$2:$G$541,MATCH(ROWS(A$6:A6),'CHOICE calc'!$E$2:$E$541,0)),"") | C6: =IFERROR(INDEX('CHOICE calc'!$H$2:$H$541,MATCH(ROWS(A$6:A6),'CHOICE calc'!$E$2:$E$541,0)),"") | D6: =IFERROR(INDEX('CHOICE calc'!$I$2:$I$541,MATCH(ROWS(A$6:A6),'CHOICE calc'!$E$2:$E$541,0)),"") | E6: =IFERROR(INDEX('CHOICE calc'!$J$2:$J$541,MATCH(ROWS(A$6:A6),'CHOICE calc'!$E$2:$E$541,0)),"") | F6: =IFERROR(INDEX('CHOICE calc'!$K$2:$K$541,MATCH(ROWS(A$6:A6),'CHOICE calc'!$E$2:$E$541,0)),"") | G6: =IFERROR(INDEX('CHOICE calc'!$L$2:$L$541,MATCH(ROWS(A$6:A6),'CHOICE calc'!$E$2:$E$541,0)),"") | H6: =IFERROR(INDEX('CHOICE calc'!$A$2:$A$541,MATCH(ROWS(A$6:A6),'CHOICE calc'!$E$2:$E$541,0)),"") | I6: Cumulative Totals - CHOICE HOURS
A7: =IFERROR(INDEX('CHOICE calc'!$F$2:$F$541,MATCH(ROWS(A$6:A7),'CHOICE calc'!$E$2:$E$541,0)),"") | B7: =IFERROR(INDEX('CHOICE calc'!$G$2:$G$541,MATCH(ROWS(A$6:A7),'CHOICE calc'!$E$2:$E$541,0)),"") | C7: =IFERROR(INDEX('CHOICE calc'!$H$2:$H$541,MATCH(ROWS(A$6:A7),'CHOICE calc'!$E$2:$E$541,0)),"") | D7: =IFERROR(INDEX('CHOICE calc'!$I$2:$I$541,MATCH(ROWS(A$6:A7),'CHOICE calc'!$E$2:$E$541,0)),"") | E7: =IFERROR(INDEX('CHOICE calc'!$J$2:$J$541,MATCH(ROWS(A$6:A7),'CHOICE calc'!$E$2:$E$541,0)),"") | F7: =IFERROR(INDEX('CHOICE calc'!$K$2:$K$541,MATCH(ROWS(A$6:A7),'CHOICE calc'!$E$2:$E$541,0)),"") | G7: =IFERROR(INDEX('CHOICE calc'!$L$2:$L$541,MATCH(ROWS(A$6:A7),'CHOICE calc'!$E$2:$E$541,0)),"") | H7: =IFERROR(INDEX('CHOICE calc'!$A$2:$A$541,MATCH(ROWS(A$6:A7),'CHOICE calc'!$E$2:$E$541,0)),"") | I7: Competency | J7: Total Min Req | K7: Align/ Choice Hours | L7: Remain
A8: =IFERROR(INDEX('CHOICE calc'!$F$2:$F$541,MATCH(ROWS(A$6:A8),'CHOICE calc'!$E$2:$E$541,0)),"") | B8: =IFERROR(INDEX('CHOICE calc'!$G$2:$G$541,MATCH(ROWS(A$6:A8),'CHOICE calc'!$E$2:$E$541,0)),"") | C8: =IFERROR(INDEX('CHOICE calc'!$H$2:$H$541,MATCH(ROWS(A$6:A8),'CHOICE calc'!$E$2:$E$541,0)),"") | D8: =IFERROR(INDEX('CHOICE calc'!$I$2:$I$541,MATCH(ROWS(A$6:A8),'CHOICE calc'!$E$2:$E$541,0)),"") | E8: =IFERROR(INDEX('CHOICE calc'!$J$2:$J$541,MATCH(ROWS(A$6:A8),'CHOICE calc'!$E$2:$E$541,0)),"") | F8: =IFERROR(INDEX('CHOICE calc'!$K$2:$K$541,MATCH(ROWS(A$6:A8),'CHOICE calc'!$E$2:$E$541,0)),"") | G8: =IFERROR(INDEX('CHOICE calc'!$L$2:$L$541,MATCH(ROWS(A$6:A8),'CHOICE calc'!$E$2:$E$541,0)),"") | H8: =IFERROR(INDEX('CHOICE calc'!$A$2:$A$541,MATCH(ROWS(A$6:A8),'CHOICE calc'!$E$2:$E$541,0)),"") | I8: 1. Instructional Leadership | J8: 3 | K8: ='📊 Dashboard'!B19 | L8: =J8-K8 | M8: NOTE: Column H "Total Min Requirements" shows you how many hours are left in each competency after embedded and aligned. There is some leeway here. You can go over or under a couple of hours if you want to focus in an area of development. On the Course Hours record tab, I make suggestions on which course may be aligned best for the competency. IT IS NOT REQUIRED you follow that guidance. Remember, you SHOULD turn in choice hours each semester (Aka the alignment) BUT we recognize that sometimes the experience doesn't align with what's going on in your schools and therefore, may submit another semester.
A9: =IFERROR(INDEX('CHOICE calc'!$F$2:$F$541,MATCH(ROWS(A$6:A9),'CHOICE calc'!$E$2:$E$541,0)),"") | B9: =IFERROR(INDEX('CHOICE calc'!$G$2:$G$541,MATCH(ROWS(A$6:A9),'CHOICE calc'!$E$2:$E$541,0)),"") | C9: =IFERROR(INDEX('CHOICE calc'!$H$2:$H$541,MATCH(ROWS(A$6:A9),'CHOICE calc'!$E$2:$E$541,0)),"") | D9: =IFERROR(INDEX('CHOICE calc'!$I$2:$I$541,MATCH(ROWS(A$6:A9),'CHOICE calc'!$E$2:$E$541,0)),"") | E9: =IFERROR(INDEX('CHOICE calc'!$J$2:$J$541,MATCH(ROWS(A$6:A9),'CHOICE calc'!$E$2:$E$541,0)),"") | F9: =IFERROR(INDEX('CHOICE calc'!$K$2:$K$541,MATCH(ROWS(A$6:A9),'CHOICE calc'!$E$2:$E$541,0)),"") | G9: =IFERROR(INDEX('CHOICE calc'!$L$2:$L$541,MATCH(ROWS(A$6:A9),'CHOICE calc'!$E$2:$E$541,0)),"") | H9: =IFERROR(INDEX('CHOICE calc'!$A$2:$A$541,MATCH(ROWS(A$6:A9),'CHOICE calc'!$E$2:$E$541,0)),"") | I9: 2. Oganizational Management | J9: 0 | K9: ='📊 Dashboard'!B20 | L9: 0
A10: =IFERROR(INDEX('CHOICE calc'!$F$2:$F$541,MATCH(ROWS(A$6:A10),'CHOICE calc'!$E$2:$E$541,0)),"") | B10: =IFERROR(INDEX('CHOICE calc'!$G$2:$G$541,MATCH(ROWS(A$6:A10),'CHOICE calc'!$E$2:$E$541,0)),"") | C10: =IFERROR(INDEX('CHOICE calc'!$H$2:$H$541,MATCH(ROWS(A$6:A10),'CHOICE calc'!$E$2:$E$541,0)),"") | D10: =IFERROR(INDEX('CHOICE calc'!$I$2:$I$541,MATCH(ROWS(A$6:A10),'CHOICE calc'!$E$2:$E$541,0)),"") | E10: =IFERROR(INDEX('CHOICE calc'!$J$2:$J$541,MATCH(ROWS(A$6:A10),'CHOICE calc'!$E$2:$E$541,0)),"") | F10: =IFERROR(INDEX('CHOICE calc'!$K$2:$K$541,MATCH(ROWS(A$6:A10),'CHOICE calc'!$E$2:$E$541,0)),"") | G10: =IFERROR(INDEX('CHOICE calc'!$L$2:$L$541,MATCH(ROWS(A$6:A10),'CHOICE calc'!$E$2:$E$541,0)),"") | H10: =IFERROR(INDEX('CHOICE calc'!$A$2:$A$541,MATCH(ROWS(A$6:A10),'CHOICE calc'!$E$2:$E$541,0)),"") | I10: 3. Operational Management | J10: 23 | K10: ='📊 Dashboard'!B21 | L10: =J10-K10
A11: =IFERROR(INDEX('CHOICE calc'!$F$2:$F$541,MATCH(ROWS(A$6:A11),'CHOICE calc'!$E$2:$E$541,0)),"") | B11: =IFERROR(INDEX('CHOICE calc'!$G$2:$G$541,MATCH(ROWS(A$6:A11),'CHOICE calc'!$E$2:$E$541,0)),"") | C11: =IFERROR(INDEX('CHOICE calc'!$H$2:$H$541,MATCH(ROWS(A$6:A11),'CHOICE calc'!$E$2:$E$541,0)),"") | D11: =IFERROR(INDEX('CHOICE calc'!$I$2:$I$541,MATCH(ROWS(A$6:A11),'CHOICE calc'!$E$2:$E$541,0)),"") | E11: =IFERROR(INDEX('CHOICE calc'!$J$2:$J$541,MATCH(ROWS(A$6:A11),'CHOICE calc'!$E$2:$E$541,0)),"") | F11: =IFERROR(INDEX('CHOICE calc'!$K$2:$K$541,MATCH(ROWS(A$6:A11),'CHOICE calc'!$E$2:$E$541,0)),"") | G11: =IFERROR(INDEX('CHOICE calc'!$L$2:$L$541,MATCH(ROWS(A$6:A11),'CHOICE calc'!$E$2:$E$541,0)),"") | H11: =IFERROR(INDEX('CHOICE calc'!$A$2:$A$541,MATCH(ROWS(A$6:A11),'CHOICE calc'!$E$2:$E$541,0)),"") | I11: 4. Systemic Equity and Community Engagement | J11: 4 | K11: ='📊 Dashboard'!B22 | L11: =J11-K11
A12: =IFERROR(INDEX('CHOICE calc'!$F$2:$F$541,MATCH(ROWS(A$6:A12),'CHOICE calc'!$E$2:$E$541,0)),"") | B12: =IFERROR(INDEX('CHOICE calc'!$G$2:$G$541,MATCH(ROWS(A$6:A12),'CHOICE calc'!$E$2:$E$541,0)),"") | C12: =IFERROR(INDEX('CHOICE calc'!$H$2:$H$541,MATCH(ROWS(A$6:A12),'CHOICE calc'!$E$2:$E$541,0)),"") | D12: =IFERROR(INDEX('CHOICE calc'!$I$2:$I$541,MATCH(ROWS(A$6:A12),'CHOICE calc'!$E$2:$E$541,0)),"") | E12: =IFERROR(INDEX('CHOICE calc'!$J$2:$J$541,MATCH(ROWS(A$6:A12),'CHOICE calc'!$E$2:$E$541,0)),"") | F12: =IFERROR(INDEX('CHOICE calc'!$K$2:$K$541,MATCH(ROWS(A$6:A12),'CHOICE calc'!$E$2:$E$541,0)),"") | G12: =IFERROR(INDEX('CHOICE calc'!$L$2:$L$541,MATCH(ROWS(A$6:A12),'CHOICE calc'!$E$2:$E$541,0)),"") | H12: =IFERROR(INDEX('CHOICE calc'!$A$2:$A$541,MATCH(ROWS(A$6:A12),'CHOICE calc'!$E$2:$E$541,0)),"") | I12: 5. Professionalism | J12: 23 | K12: ='📊 Dashboard'!B23 | L12: =J12-K12
A13: =IFERROR(INDEX('CHOICE calc'!$F$2:$F$541,MATCH(ROWS(A$6:A13),'CHOICE calc'!$E$2:$E$541,0)),"") | B13: =IFERROR(INDEX('CHOICE calc'!$G$2:$G$541,MATCH(ROWS(A$6:A13),'CHOICE calc'!$E$2:$E$541,0)),"") | C13: =IFERROR(INDEX('CHOICE calc'!$H$2:$H$541,MATCH(ROWS(A$6:A13),'CHOICE calc'!$E$2:$E$541,0)),"") | D13: =IFERROR(INDEX('CHOICE calc'!$I$2:$I$541,MATCH(ROWS(A$6:A13),'CHOICE calc'!$E$2:$E$541,0)),"") | E13: =IFERROR(INDEX('CHOICE calc'!$J$2:$J$541,MATCH(ROWS(A$6:A13),'CHOICE calc'!$E$2:$E$541,0)),"") | F13: =IFERROR(INDEX('CHOICE calc'!$K$2:$K$541,MATCH(ROWS(A$6:A13),'CHOICE calc'!$E$2:$E$541,0)),"") | G13: =IFERROR(INDEX('CHOICE calc'!$L$2:$L$541,MATCH(ROWS(A$6:A13),'CHOICE calc'!$E$2:$E$541,0)),"") | H13: =IFERROR(INDEX('CHOICE calc'!$A$2:$A$541,MATCH(ROWS(A$6:A13),'CHOICE calc'!$E$2:$E$541,0)),"") | I13: 6. Advocacy | J13: 17 | K13: ='📊 Dashboard'!B24 | L13: =J13-K13
A14: =IFERROR(INDEX('CHOICE calc'!$F$2:$F$541,MATCH(ROWS(A$6:A14),'CHOICE calc'!$E$2:$E$541,0)),"") | B14: =IFERROR(INDEX('CHOICE calc'!$G$2:$G$541,MATCH(ROWS(A$6:A14),'CHOICE calc'!$E$2:$E$541,0)),"") | C14: =IFERROR(INDEX('CHOICE calc'!$H$2:$H$541,MATCH(ROWS(A$6:A14),'CHOICE calc'!$E$2:$E$541,0)),"") | D14: =IFERROR(INDEX('CHOICE calc'!$I$2:$I$541,MATCH(ROWS(A$6:A14),'CHOICE calc'!$E$2:$E$541,0)),"") | E14: =IFERROR(INDEX('CHOICE calc'!$J$2:$J$541,MATCH(ROWS(A$6:A14),'CHOICE calc'!$E$2:$E$541,0)),"") | F14: =IFERROR(INDEX('CHOICE calc'!$K$2:$K$541,MATCH(ROWS(A$6:A14),'CHOICE calc'!$E$2:$E$541,0)),"") | G14: =IFERROR(INDEX('CHOICE calc'!$L$2:$L$541,MATCH(ROWS(A$6:A14),'CHOICE calc'!$E$2:$E$541,0)),"") | H14: =IFERROR(INDEX('CHOICE calc'!$A$2:$A$541,MATCH(ROWS(A$6:A14),'CHOICE calc'!$E$2:$E$541,0)),"")
A15: =IFERROR(INDEX('CHOICE calc'!$F$2:$F$541,MATCH(ROWS(A$6:A15),'CHOICE calc'!$E$2:$E$541,0)),"") | B15: =IFERROR(INDEX('CHOICE calc'!$G$2:$G$541,MATCH(ROWS(A$6:A15),'CHOICE calc'!$E$2:$E$541,0)),"") | C15: =IFERROR(INDEX('CHOICE calc'!$H$2:$H$541,MATCH(ROWS(A$6:A15),'CHOICE calc'!$E$2:$E$541,0)),"") | D15: =IFERROR(INDEX('CHOICE calc'!$I$2:$I$541,MATCH(ROWS(A$6:A15),'CHOICE calc'!$E$2:$E$541,0)),"") | E15: =IFERROR(INDEX('CHOICE calc'!$J$2:$J$541,MATCH(ROWS(A$6:A15),'CHOICE calc'!$E$2:$E$541,0)),"") | F15: =IFERROR(INDEX('CHOICE calc'!$K$2:$K$541,MATCH(ROWS(A$6:A15),'CHOICE calc'!$E$2:$E$541,0)),"") | G15: =IFERROR(INDEX('CHOICE calc'!$L$2:$L$541,MATCH(ROWS(A$6:A15),'CHOICE calc'!$E$2:$E$541,0)),"") | H15: =IFERROR(INDEX('CHOICE calc'!$A$2:$A$541,MATCH(ROWS(A$6:A15),'CHOICE calc'!$E$2:$E$541,0)),"")
A16: =IFERROR(INDEX('CHOICE calc'!$F$2:$F$541,MATCH(ROWS(A$6:A16),'CHOICE calc'!$E$2:$E$541,0)),"") | B16: =IFERROR(INDEX('CHOICE calc'!$G$2:$G$541,MATCH(ROWS(A$6:A16),'CHOICE calc'!$E$2:$E$541,0)),"") | C16: =IFERROR(INDEX('CHOICE calc'!$H$2:$H$541,MATCH(ROWS(A$6:A16),'CHOICE calc'!$E$2:$E$541,0)),"") | D16: =IFERROR(INDEX('CHOICE calc'!$I$2:$I$541,MATCH(ROWS(A$6:A16),'CHOICE calc'!$E$2:$E$541,0)),"") | E16: =IFERROR(INDEX('CHOICE calc'!$J$2:$J$541,MATCH(ROWS(A$6:A16),'CHOICE calc'!$E$2:$E$541,0)),"") | F16: =IFERROR(INDEX('CHOICE calc'!$K$2:$K$541,MATCH(ROWS(A$6:A16),'CHOICE calc'!$E$2:$E$541,0)),"") | G16: =IFERROR(INDEX('CHOICE calc'!$L$2:$L$541,MATCH(ROWS(A$6:A16),'CHOICE calc'!$E$2:$E$541,0)),"") | H16: =IFERROR(INDEX('CHOICE calc'!$A$2:$A$541,MATCH(ROWS(A$6:A16),'CHOICE calc'!$E$2:$E$541,0)),"")
A17: =IFERROR(INDEX('CHOICE calc'!$F$2:$F$541,MATCH(ROWS(A$6:A17),'CHOICE calc'!$E$2:$E$541,0)),"") | B17: =IFERROR(INDEX('CHOICE calc'!$G$2:$G$541,MATCH(ROWS(A$6:A17),'CHOICE calc'!$E$2:$E$541,0)),"") | C17: =IFERROR(INDEX('CHOICE calc'!$H$2:$H$541,MATCH(ROWS(A$6:A17),'CHOICE calc'!$E$2:$E$541,0)),"") | D17: =IFERROR(INDEX('CHOICE calc'!$I$2:$I$541,MATCH(ROWS(A$6:A17),'CHOICE calc'!$E$2:$E$541,0)),"") | E17: =IFERROR(INDEX('CHOICE calc'!$J$2:$J$541,MATCH(ROWS(A$6:A17),'CHOICE calc'!$E$2:$E$541,0)),"") | F17: =IFERROR(INDEX('CHOICE calc'!$K$2:$K$541,MATCH(ROWS(A$6:A17),'CHOICE calc'!$E$2:$E$541,0)),"") | G17: =IFERROR(INDEX('CHOICE calc'!$L$2:$L$541,MATCH(ROWS(A$6:A17),'CHOICE calc'!$E$2:$E$541,0)),"") | H17: =IFERROR(INDEX('CHOICE calc'!$A$2:$A$541,MATCH(ROWS(A$6:A17),'CHOICE calc'!$E$2:$E$541,0)),"")
A18: =IFERROR(INDEX('CHOICE calc'!$F$2:$F$541,MATCH(ROWS(A$6:A18),'CHOICE calc'!$E$2:$E$541,0)),"") | B18: =IFERROR(INDEX('CHOICE calc'!$G$2:$G$541,MATCH(ROWS(A$6:A18),'CHOICE calc'!$E$2:$E$541,0)),"") | C18: =IFERROR(INDEX('CHOICE calc'!$H$2:$H$541,MATCH(ROWS(A$6:A18),'CHOICE calc'!$E$2:$E$541,0)),"") | D18: =IFERROR(INDEX('CHOICE calc'!$I$2:$I$541,MATCH(ROWS(A$6:A18),'CHOICE calc'!$E$2:$E$541,0)),"") | E18: =IFERROR(INDEX('CHOICE calc'!$J$2:$J$541,MATCH(ROWS(A$6:A18),'CHOICE calc'!$E$2:$E$541,0)),"") | F18: =IFERROR(INDEX('CHOICE calc'!$K$2:$K$541,MATCH(ROWS(A$6:A18),'CHOICE calc'!$E$2:$E$541,0)),"") | G18: =IFERROR(INDEX('CHOICE calc'!$L$2:$L$541,MATCH(ROWS(A$6:A18),'CHOICE calc'!$E$2:$E$541,0)),"") | H18: =IFERROR(INDEX('CHOICE calc'!$A$2:$A$541,MATCH(ROWS(A$6:A18),'CHOICE calc'!$E$2:$E$541,0)),"")
A19: =IFERROR(INDEX('CHOICE calc'!$F$2:$F$541,MATCH(ROWS(A$6:A19),'CHOICE calc'!$E$2:$E$541,0)),"") | B19: =IFERROR(INDEX('CHOICE calc'!$G$2:$G$541,MATCH(ROWS(A$6:A19),'CHOICE calc'!$E$2:$E$541,0)),"") | C19: =IFERROR(INDEX('CHOICE calc'!$H$2:$H$541,MATCH(ROWS(A$6:A19),'CHOICE calc'!$E$2:$E$541,0)),"") | D19: =IFERROR(INDEX('CHOICE calc'!$I$2:$I$541,MATCH(ROWS(A$6:A19),'CHOICE calc'!$E$2:$E$541,0)),"") | E19: =IFERROR(INDEX('CHOICE calc'!$J$2:$J$541,MATCH(ROWS(A$6:A19),'CHOICE calc'!$E$2:$E$541,0)),"") | F19: =IFERROR(INDEX('CHOICE calc'!$K$2:$K$541,MATCH(ROWS(A$6:A19),'CHOICE calc'!$E$2:$E$541,0)),"") | G19: =IFERROR(INDEX('CHOICE calc'!$L$2:$L$541,MATCH(ROWS(A$6:A19),'CHOICE calc'!$E$2:$E$541,0)),"") | H19: =IFERROR(INDEX('CHOICE calc'!$A$2:$A$541,MATCH(ROWS(A$6:A19),'CHOICE calc'!$E$2:$E$541,0)),"")
A20: =IFERROR(INDEX('CHOICE calc'!$F$2:$F$541,MATCH(ROWS(A$6:A20),'CHOICE calc'!$E$2:$E$541,0)),"") | B20: =IFERROR(INDEX('CHOICE calc'!$G$2:$G$541,MATCH(ROWS(A$6:A20),'CHOICE calc'!$E$2:$E$541,0)),"") | C20: =IFERROR(INDEX('CHOICE calc'!$H$2:$H$541,MATCH(ROWS(A$6:A20),'CHOICE calc'!$E$2:$E$541,0)),"") | D20: =IFERROR(INDEX('CHOICE calc'!$I$2:$I$541,MATCH(ROWS(A$6:A20),'CHOICE calc'!$E$2:$E$541,0)),"") | E20: =IFERROR(INDEX('CHOICE calc'!$J$2:$J$541,MATCH(ROWS(A$6:A20),'CHOICE calc'!$E$2:$E$541,0)),"") | F20: =IFERROR(INDEX('CHOICE calc'!$K$2:$K$541,MATCH(ROWS(A$6:A20),'CHOICE calc'!$E$2:$E$541,0)),"") | G20: =IFERROR(INDEX('CHOICE calc'!$L$2:$L$541,MATCH(ROWS(A$6:A20),'CHOICE calc'!$E$2:$E$541,0)),"") | H20: =IFERROR(INDEX('CHOICE calc'!$A$2:$A$541,MATCH(ROWS(A$6:A20),'CHOICE calc'!$E$2:$E$541,0)),"")
A21: =IFERROR(INDEX('CHOICE calc'!$F$2:$F$541,MATCH(ROWS(A$6:A21),'CHOICE calc'!$E$2:$E$541,0)),"") | B21: =IFERROR(INDEX('CHOICE calc'!$G$2:$G$541,MATCH(ROWS(A$6:A21),'CHOICE calc'!$E$2:$E$541,0)),"") | C21: =IFERROR(INDEX('CHOICE calc'!$H$2:$H$541,MATCH(ROWS(A$6:A21),'CHOICE calc'!$E$2:$E$541,0)),"") | D21: =IFERROR(INDEX('CHOICE calc'!$I$2:$I$541,MATCH(ROWS(A$6:A21),'CHOICE calc'!$E$2:$E$541,0)),"") | E21: =IFERROR(INDEX('CHOICE calc'!$J$2:$J$541,MATCH(ROWS(A$6:A21),'CHOICE calc'!$E$2:$E$541,0)),"") | F21: =IFERROR(INDEX('CHOICE calc'!$K$2:$K$541,MATCH(ROWS(A$6:A21),'CHOICE calc'!$E$2:$E$541,0)),"") | G21: =IFERROR(INDEX('CHOICE calc'!$L$2:$L$541,MATCH(ROWS(A$6:A21),'CHOICE calc'!$E$2:$E$541,0)),"") | H21: =IFERROR(INDEX('CHOICE calc'!$A$2:$A$541,MATCH(ROWS(A$6:A21),'CHOICE calc'!$E$2:$E$541,0)),"")
A22: =IFERROR(INDEX('CHOICE calc'!$F$2:$F$541,MATCH(ROWS(A$6:A22),'CHOICE calc'!$E$2:$E$541,0)),"") | B22: =IFERROR(INDEX('CHOICE calc'!$G$2:$G$541,MATCH(ROWS(A$6:A22),'CHOICE calc'!$E$2:$E$541,0)),"") | C22: =IFERROR(INDEX('CHOICE calc'!$H$2:$H$541,MATCH(ROWS(A$6:A22),'CHOICE calc'!$E$2:$E$541,0)),"") | D22: =IFERROR(INDEX('CHOICE calc'!$I$2:$I$541,MATCH(ROWS(A$6:A22),'CHOICE calc'!$E$2:$E$541,0)),"") | E22: =IFERROR(INDEX('CHOICE calc'!$J$2:$J$541,MATCH(ROWS(A$6:A22),'CHOICE calc'!$E$2:$E$541,0)),"") | F22: =IFERROR(INDEX('CHOICE calc'!$K$2:$K$541,MATCH(ROWS(A$6:A22),'CHOICE calc'!$E$2:$E$541,0)),"") | G22: =IFERROR(INDEX('CHOICE calc'!$L$2:$L$541,MATCH(ROWS(A$6:A22),'CHOICE calc'!$E$2:$E$541,0)),"") | H22: =IFERROR(INDEX('CHOICE calc'!$A$2:$A$541,MATCH(ROWS(A$6:A22),'CHOICE calc'!$E$2:$E$541,0)),"")
A23: =IFERROR(INDEX('CHOICE calc'!$F$2:$F$541,MATCH(ROWS(A$6:A23),'CHOICE calc'!$E$2:$E$541,0)),"") | B23: =IFERROR(INDEX('CHOICE calc'!$G$2:$G$541,MATCH(ROWS(A$6:A23),'CHOICE calc'!$E$2:$E$541,0)),"") | C23: =IFERROR(INDEX('CHOICE calc'!$H$2:$H$541,MATCH(ROWS(A$6:A23),'CHOICE calc'!$E$2:$E$541,0)),"") | D23: =IFERROR(INDEX('CHOICE calc'!$I$2:$I$541,MATCH(ROWS(A$6:A23),'CHOICE calc'!$E$2:$E$541,0)),"") | E23: =IFERROR(INDEX('CHOICE calc'!$J$2:$J$541,MATCH(ROWS(A$6:A23),'CHOICE calc'!$E$2:$E$541,0)),"") | F23: =IFERROR(INDEX('CHOICE calc'!$K$2:$K$541,MATCH(ROWS(A$6:A23),'CHOICE calc'!$E$2:$E$541,0)),"") | G23: =IFERROR(INDEX('CHOICE calc'!$L$2:$L$541,MATCH(ROWS(A$6:A23),'CHOICE calc'!$E$2:$E$541,0)),"") | H23: =IFERROR(INDEX('CHOICE calc'!$A$2:$A$541,MATCH(ROWS(A$6:A23),'CHOICE calc'!$E$2:$E$541,0)),"")
A24: =IFERROR(INDEX('CHOICE calc'!$F$2:$F$541,MATCH(ROWS(A$6:A24),'CHOICE calc'!$E$2:$E$541,0)),"") | B24: =IFERROR(INDEX('CHOICE calc'!$G$2:$G$541,MATCH(ROWS(A$6:A24),'CHOICE calc'!$E$2:$E$541,0)),"") | C24: =IFERROR(INDEX('CHOICE calc'!$H$2:$H$541,MATCH(ROWS(A$6:A24),'CHOICE calc'!$E$2:$E$541,0)),"") | D24: =IFERROR(INDEX('CHOICE calc'!$I$2:$I$541,MATCH(ROWS(A$6:A24),'CHOICE calc'!$E$2:$E$541,0)),"") | E24: =IFERROR(INDEX('CHOICE calc'!$J$2:$J$541,MATCH(ROWS(A$6:A24),'CHOICE calc'!$E$2:$E$541,0)),"") | F24: =IFERROR(INDEX('CHOICE calc'!$K$2:$K$541,MATCH(ROWS(A$6:A24),'CHOICE calc'!$E$2:$E$541,0)),"") | G24: =IFERROR(INDEX('CHOICE calc'!$L$2:$L$541,MATCH(ROWS(A$6:A24),'CHOICE calc'!$E$2:$E$541,0)),"") | H24: =IFERROR(INDEX('CHOICE calc'!$A$2:$A$541,MATCH(ROWS(A$6:A24),'CHOICE calc'!$E$2:$E$541,0)),"")
A25: =IFERROR(INDEX('CHOICE calc'!$F$2:$F$541,MATCH(ROWS(A$6:A25),'CHOICE calc'!$E$2:$E$541,0)),"") | B25: =IFERROR(INDEX('CHOICE calc'!$G$2:$G$541,MATCH(ROWS(A$6:A25),'CHOICE calc'!$E$2:$E$541,0)),"") | C25: =IFERROR(INDEX('CHOICE calc'!$H$2:$H$541,MATCH(ROWS(A$6:A25),'CHOICE calc'!$E$2:$E$541,0)),"") | D25: =IFERROR(INDEX('CHOICE calc'!$I$2:$I$541,MATCH(ROWS(A$6:A25),'CHOICE calc'!$E$2:$E$541,0)),"") | E25: =IFERROR(INDEX('CHOICE calc'!$J$2:$J$541,MATCH(ROWS(A$6:A25),'CHOICE calc'!$E$2:$E$541,0)),"") | F25: =IFERROR(INDEX('CHOICE calc'!$K$2:$K$541,MATCH(ROWS(A$6:A25),'CHOICE calc'!$E$2:$E$541,0)),"") | G25: =IFERROR(INDEX('CHOICE calc'!$L$2:$L$541,MATCH(ROWS(A$6:A25),'CHOICE calc'!$E$2:$E$541,0)),"") | H25: =IFERROR(INDEX('CHOICE calc'!$A$2:$A$541,MATCH(ROWS(A$6:A25),'CHOICE calc'!$E$2:$E$541,0)),"")
... A139: =IFERROR(INDEX('CHOICE calc'!$F$2:$F$541,MATCH(ROWS(A$6:A139),'CHOICE calc'!$E$2:$E$541,0)),"") | B139: =IFERROR(INDEX('CHOICE calc'!$G$2:$G$541,MATCH(ROWS(A$6:A139),'CHOICE calc'!$E$2:$E$541,0)),"") | C139: =IFERROR(INDEX('CHOICE calc'!$H$2:$H$541,MATCH(ROWS(A$6:A139),'CHOICE calc'!$E$2:$E$541,0)),"") | D139: =IFERROR(INDEX('CHOICE calc'!$I$2:$I$541,MATCH(ROWS(A$6:A139),'CHOICE calc'!$E$2:$E$541,0)),"") | E139: =IFERROR(INDEX('CHOICE calc'!$J$2:$J$541,MATCH(ROWS(A$6:A139),'CHOICE calc'!$E$2:$E$541,0)),"") | F139: =IFERROR(INDEX('CHOICE calc'!$K$2:$K$541,MATCH(ROWS(A$6:A139),'CHOICE calc'!$E$2:$E$541,0)),"") | G139: =IFERROR(INDEX('CHOICE calc'!$L$2:$L$541,MATCH(ROWS(A$6:A139),'CHOICE calc'!$E$2:$E$541,0)),"") | H139: =IFERROR(INDEX('CHOICE calc'!$A$2:$A$541,MATCH(ROWS(A$6:A139),'CHOICE calc'!$E$2:$E$541,0)),"")

Sheet 📚 Competencies
A1: 📚 VIRGINIA SCHOOL LEADER COMPETENCIES
A2: 1. Instructional Leadership
B3: Knowledge, understanding, and application of planning, assessment, and instructional strategies that improve student achievement. Leaders facilitate the development and implementation of a shared vision for learning, promote a positive school culture, and provide coaching and feedback to teachers.
A5: 2. Organizational Management
B6: Knowledge, understanding, and application of leadership and management skills that promote student achievement. Leaders manage the organization, operations, and resources of a school in a way that promotes a safe, efficient, and effective learning environment.
A8: 3. Operational Management
B9: Knowledge, understanding, and application of management and organizational theories. Leaders manage human resources including recruitment, hiring, induction, professional development, evaluation, and dismissal of personnel in a fair, equitable, and legal manner.
A11: 4. Systemic Equity & Community Engagement
B12: Knowledge, understanding, and application of the conditions required to ensure equitable access and opportunity for all students. Leaders foster inclusive school communities by engaging families, caregivers, and community partners in meaningful and culturally responsive ways.
A14: 5. Professionalism
B15: Knowledge, understanding, and application of the conditions that lead to professional growth. Leaders demonstrate ethical behavior, model continuous learning, and create a culture of reflection and professional inquiry. They communicate effectively and build positive, collaborative relationships.
A17: 6. Advocacy
B18: Knowledge, understanding, and application of basic leadership skills to advocate for students, families, and school communities. Leaders act as advocates for equity and excellence, engage in policy processes, and champion the needs of all learners in public forums.

Sheet ⭐ Choice Library-All Aligned
A1: THIS TAB HAS BEEN UPDATED
A2: NOTE: YOU DO NOT NEED CHOICE HOURS IN EVERY COMPETENCY
A3: 1. Check your data tab and find "CHOICE". Within the BLUE table, identify where you have remaining hours. | B3: 2. Identify an experience you have or will engage in. CTL F a key word (Data, School Improvement, etc.) | C3: 3. Scroll over and copy the entry aligned to the competency you wish to include. Add to your planning log and then identify the alignment, hours, location, setting and your role. | D3: 4. Return to your data tab and if you have entered correctly, your tab should update showing you the hours reduced in the competency selected. | E3: 5. Continue adding experiences as you plan your internship. It is ok to plan ahead, but be sure to track if you've entered into PowerBI
A4: Virginia School Leader Internship – Competency Alignment Matrix
A5: Internship Experience | B5: Competency 1 Instructional Leadership | C5: Competency 2 Organizational Leadership | D5: Competency 3 Operational Management | E5: Competency 4 Systemic Equity | F5: Competency 5 Professionalism | G5: Competency 6 Advocacy
A6: Use survey data to gather input for planning | B6: Analyze survey results from teachers, students, or parents to identify instructional needs and inform school improvement planning. | C6: Use survey findings to align organizational practices with school community priorities and develop strategic improvement goals. | D6: Leverage survey data to make management decisions that improve the working and learning climate and support staff effectiveness. | E6: Gather diverse community input through surveys to identify equity gaps and emerging needs affecting underrepresented student populations. | F6: Model ethical, inclusive data practices by ensuring survey processes respect all stakeholders and reflect a commitment to fairness and equity. | G6: Use community voice data to advocate for policies and resources that address systemic needs identified through stakeholder surveys.
A7: Lead a focus group on school improvement needs | B7: Facilitate a staff focus group to identify instructional improvement priorities and align findings with school improvement planning. | C7: Lead a structured focus group to gather stakeholder input that informs strategic planning and organizational alignment with division goals. | D7: Use focus group findings to inform operational management decisions related to staffing, professional development, and resource allocation. | E7: Conduct a focus group that elevates the voices of diverse community members to surface equity-related needs and improvement priorities. | F7: Model reflective professional practice by facilitating inclusive, honest dialogue that upholds ethical standards in decision-making. | G7: Leverage focus group findings to advocate for school-level policy changes and resource investments aligned with community-identified needs.
A8: Identify community resources for diverse students | B8: Connect instructional support to community resources that address diverse student learning needs, including ELL and special education services. | C8: Build strategic partnerships with community organizations to expand the school's capacity to serve diverse populations through coordinated planning. | D8: Manage community partnerships as an operational function that supports student success, safety, and access to services. | E8: Identify and mobilize community resources specifically targeted toward underserved student populations to advance systemic equity. | F8: Demonstrate a professional commitment to equity by actively seeking partnerships that reflect fairness, care, and responsiveness to diverse student needs. | G8: Advocate for increased community support and external resources to address gaps in services for diverse and underrepresented students.
